Traceback (most recent call last):
  File "c:\Users\VargasO\OneDrive - HP Inc\Python Softtek\PythonSofttekOrlando\Udemy\raise and assert.py", line 24, in <module>
    raise Exception("This is the error message")
Exception: This is the error message
Traceback (most recent call last):
  File "c:\Users\VargasO\OneDrive - HP Inc\Python Softtek\PythonSofttekOrlando\Udemy\raise and assert.py", line 24, in <module>
    raise Exception("This is the error message")
Exception: This is the error message
Traceback (most recent call last):
  File "c:\Users\VargasO\OneDrive - HP Inc\Python Softtek\PythonSofttekOrlando\Udemy\raise and assert.py", line 24, in <module>
    raise Exception("This is the error message")
Exception: This is the error message
Traceback (most recent call last):
  File "c:\Users\VargasO\OneDrive - HP Inc\Python Softtek\PythonSofttekOrlando\Udemy\raise and assert.py", line 24, in <module>
    raise Exception("This is the error message")
Exception: This is the error message
Traceback (most recent call last):
  File "c:\Users\VargasO\OneDrive - HP Inc\Python Softtek\PythonSofttekOrlando\Udemy\raise and assert.py", line 24, in <module>
    raise Exception("This is the error message")
Exception: This is the error message
